Workbook

Sheet RESUMEN
A1: RESUMEN · cupo Sinosure y deuda con China
A2: Todo se calcula solo desde la hoja PEDIDOS. Lo único que se escribe aquí son los dos techos de cupo.
A3: Regla para contar el cupo
A4: (se elige aquí y toda la hoja PEDIDOS se recalcula) | B4: Monto en fábrica · saldo cuando embarque | C4: Un pedido Por confirmar o Cerrado nunca consume cupo, sin importar la regla.
A6: CUPO SINOSURE
B7: Singsun · trackers | C7: Eaglerise · shelters
A8: Techo de cupo | B8: 1300000 | C8: 3000000 | D8: Lo escribes tú
A9: Consumo (pedidos confirmados) | B9: =SUMIFS(PEDIDOS!$AI$4:$AI$200,PEDIDOS!$C$4:$C$200,"Singsun") | C9: =SUMIFS(PEDIDOS!$AI$4:$AI$200,PEDIDOS!$C$4:$C$200,"Eaglerise") | D9: Suma de la columna AI
A10: Cupo disponible | B10: =B8-B9 | C10: =C8-C9 | D10: Negativo = sobregirado
A11: Sin confirmar (proyección) | B11: =SUMIFS(PEDIDOS!$P$4:$P$200,PEDIDOS!$C$4:$C$200,"Singsun",PEDIDOS!$H$4:$H$200,"Por confirmar") | C11: =SUMIFS(PEDIDOS!$P$4:$P$200,PEDIDOS!$C$4:$C$200,"Eaglerise",PEDIDOS!$H$4:$H$200,"Por confirmar") | D11: Pedidos aún no confirmados
A12: Disponible si se confirman | B12: =B10-B11 | C12: =C10-C11
A14: LO QUE SE LE DEBE A CHINA
A15: Saldo con los fabricantes | B15: =SUM(PEDIDOS!$AA$4:$AA$200) | C15: Lo cubre el cupo Sinosure
A16: Saldo de otros componentes | B16: =SUM(PEDIDOS!$AD$4:$AD$200) | C16: Por fuera del cupo · se paga de inmediato
A17: SALDO TOTAL A CHINA | B17: =SUM(PEDIDOS!$AG$4:$AG$200)
A18: Vencido a hoy | B18: =SUMIFS(PEDIDOS!$V$4:$V$200,PEDIDOS!$X$4:$X$200,"Pendiente",PEDIDOS!$W$4:$W$200,"<"&TODAY()) | C18: Balances con fecha ya pasada
A20: REVISIÓN ANTES DE ENVIAR
A21: Pedidos cargados | B21: =COUNTA(PEDIDOS!$A$4:$A$200)
A22: Filas con alertas | B22: =COUNTIF(PEDIDOS!$AJ$4:$AJ$200,"?*") | C22: Tiene que quedar en cero
A23: Líneas de otros componentes con alertas | B23: =COUNTIF('OTROS COMPONENTES'!$I$4:$I$200,"?*") | C23: Tiene que quedar en cero

Sheet INSTRUCCIONES
A1: CÓMO SE LLENA ESTE ARCHIVO
A2: Zentrack · formato propuesto para reemplazar el ORDER REPORT y el Detailed order and operational fund report
A4: LO QUE CAMBIA
A5: Un solo archivo | B5: Este archivo reemplaza al ORDER REPORT y al Detailed order and operational fund report. Todo lo que hoy está repartido en dos libros vive aquí, y nada se repite en dos sitios.
A6: Tres hojas | B6: RESUMEN se calcula solo. PEDIDOS y OTROS COMPONENTES son las que se llenan. No hay que mantener una hoja de Sinosure aparte: el consumo de cupo sale de una fórmula por pedido.
A7: Crema se llena, gris no se toca | B7: Las celdas con fondo crema son para escribir. Las grises tienen fórmulas: si se pisan con un número a mano, el archivo deja de cuadrar.
A9: LAS DIEZ REGLAS
A10: 1. Una fila por pedido | B10: Cada fila es un ID_Pedido y nada más. Si de la orden 7 salen el 7-2, el 7-3 y el 7-4, son tres filas.
A11: 2. Nunca la orden madre y sus pedidos a la vez | B11: Cuando una orden se parte, la fila de la orden completa se marca como Cerrado o se borra. Hoy el 7-5 aparece dos veces: una con 293.698 (que en realidad son el 7-5 al 7-9 juntos) y otra con 61.744. Esa duplicidad es la que descuadra el cupo.
A12: 3. Un proyecto por fila | B12: Si un pedido lleva dos proyectos, van dos filas. Nada de "Santo Tomás Sur 1/2" en una sola. Es la única forma de saber a qué proyecto se le carga cada dólar.
A13: 4. El ID_Pedido va limpio | B13: 7-2, CFM3-4, 12. Sin nombres de proyecto pegados. Hoy hay IDs como "PO12 SOLARIS INGEV" o "PO#10 INGEV1 MARIANGOLA": el nombre va en la columna Proyecto.
A14: 5. Las listas son cerradas | B14: Fabricante, Equipo, Estado, Telex y los estados de pago se eligen de la lista desplegable. Escribir algo distinto hace que la celda lo rechace.
A15: 6. En dinero, nunca un guión | B15: Una celda de dinero lleva un número o se deja vacía. Un "-" o un "n/a" hace que el total deje de sumar.
A16: 7. El estado de un pago nunca va en blanco | B16: Pagado o Pendiente, siempre. Hoy hay pagos con monto y sin estado, y no hay forma de saber si esa plata ya salió.
A17: 8. Los montos no se redondean a mano | B17: El costo del fabricante se escribe tal como está en la orden. Las fórmulas hacen el resto.
A18: 9. Lo que no está confirmado va como Por confirmar | B18: Un pedido que todavía no se cierra con el fabricante se deja en ese estado: no consume cupo, pero queda visible en el RESUMEN como proyección. Hoy el PO16 no aparece en la hoja de Sinosure y no había forma de saber por qué.
A19: 10. La columna Alertas queda en cero | B19: Antes de enviar el archivo, revisa el RESUMEN: "Filas con alertas" tiene que decir 0. Si dice otra cosa, la columna Alertas de cada hoja dice exactamente qué falta.
A21: CÓMO SE CALCULA EL CUPO SINOSURE
A22: La regla | B22: Un pedido Por confirmar o Cerrado no consume cupo. Un pedido ya embarcado consume el saldo que falta pagarle al fabricante. Un pedido que sigue en fábrica consume el costo completo.
A23: Por qué así | B23: Es la regla que se dedujo de cómo está armada hoy la hoja de Sinosure. Con ella el archivo da los mismos totales que reporta hoy. Si la regla real es otra, se cambia la fórmula de la columna AI y todo lo demás se recalcula solo.
A24: Lo que ya no hace falta | B24: La hoja de Sinosure aparte. Hoy sus renglones apuntan a celdas del Summary y hay dos que apuntan a la misma (el CFM 3.2 se cuenta dos veces, 103.040 de más). Con el consumo como columna por pedido eso no puede volver a pasar.
A26: LO QUE NO VA EN ESTE ARCHIVO
A27: Precios de venta | B27: El precio al que Zentrack le vende a sus clientes no va aquí. Eso lo maneja Esteban aparte.
A28: Facturas a clientes | B28: Tampoco. Este archivo es solo la relación con China.
A30: SI APARECE ALGO NUEVO
A31: Un proveedor nuevo | B31: Se escribe en la hoja OTROS COMPONENTES y ya. No hay que agregar columnas.
A32: Un pago extra | B32: Si un pedido necesita más de un anticipo o más de un balance, se suman en la misma celda y se aclara en Notas. Si empieza a pasar seguido, se agregan columnas.
A33: Un cliente nuevo | B33: Se escribe en la columna Cliente. La lista es una ayuda, no una restricción.
A35: LEYENDA DE COLORES
B36: Se llena a mano
B37: Fórmula · no se toca

Sheet PEDIDOS
A1: ORDER REPORT ZENTRACK · hoja única
A2: Una fila por pedido. Las columnas con fondo crema las llena Andrés; las grises son fórmulas y no se tocan. Revisa la columna Alertas antes de enviar el archivo.
A3: ID_Pedido | B3: Orden | C3: Fabricante | D3: Equipo | E3: Cant. | F3: Proyecto | G3: Cliente | H3: Estado | I3: Fecha de pedido | J3: Fin de producción | K3: ETD | L3: Fecha BL real | M3: ETA | N3: BL No. | O3: Telex | P3: Costo fabricante | Q3: Anticipo % | R3: Anticipo USD | S3: Anticipo vence | T3: Anticipo estado | U3: Anticipo pagado el | V3: Balance USD | W3: Balance vence | X3: Balance estado | Y3: Balance pagado el | Z3: Pagado al fabricante | AA3: Saldo con el fabricante | AB3: Otros comp. monto | AC3: Otros comp. pagado | AD3: Otros comp. saldo | AE3: Costo total China | AF3: Pagado total China | AG3: SALDO TOTAL A CHINA | AH3: ¿Consume cupo? | AI3: Consumo cupo Sinosure | AJ3: Alertas | AK3: Notas
A4: 7-2 | B4: 7 | C4: Singsun | D4: Tracker | E4: 2 | F4: Santo Tomás Sur 1/2 | G4: Solenium | H4: Embarcado | J4: 46113 | K4: 46206 | M4: 46229 | N4: NSHEC260656679/680 | O4: Released | P4: 132361.2 | Q4: 0.1 | R4: =IF($A4="","",ROUND(P4*Q4,2)) | T4: Pagado | U4: 46094 | V4: =IF($A4="","",ROUND(P4-R4,2)) | W4: 46296 | X4: Pendiente | Z4: =IF($A4="","",IF(T4="Pagado",N(R4),0)+IF(X4="Pagado",N(V4),0)) | AA4: =IF($A4="","",ROUND(N(P4)-N(Z4),2)) | AB4: =IF($A4="","",SUMIF('OTROS COMPONENTES'!$A$4:$A$200,$A4,'OTROS COMPONENTES'!$D$4:$D$200)) | AC4: =IF($A4="","",SUMIF('OTROS COMPONENTES'!$A$4:$A$200,$A4,'OTROS COMPONENTES'!$E$4:$E$200)) | AD4: =IF($A4="","",ROUND(N(AB4)-N(AC4),2)) | AE4: =IF($A4="","",ROUND(N(P4)+N(AB4),2)) | AF4: =IF($A4="","",ROUND(N(Z4)+N(AC4),2)) | AG4: =IF($A4="","",ROUND(N(AA4)+N(AD4),2)) | AH4: =IF($A4="","",IF(OR($H4="Por confirmar",$H4="Cerrado"),"No","Sí")) | AI4: =IF($A4="","",IF(AH4="No",0,IF(RESUMEN!$B$4="Saldo por pagar al fabricante",AA4,IF(RESUMEN!$B$4="Monto completo del pedido",P4,IF(OR($H4="Embarcando",$H4="Embarcado"),N(AA4),N(P4)))))) | AJ4: =IF($A4="","",IF(COUNTIF($A$4:$A$200,$A4)>1,"ID_Pedido repetido",IF(N($P4)<=0,"Falta el costo del fabricante",IF($F4="","Falta el proyecto",IF($G4="","Falta el cliente",IF(AND($H4<>"Por confirmar",N($R4)>0,$T4=""),"Falta el estado del anticipo",IF(AND($H4<>"Por confirmar",N($V4)>0,$X4=""),"Falta el estado del balance",IF($E4>1,""&$E4&" equipos en una fila: pártela en una por proyecto",IF(AND($X4="Pendiente",N($V4)>0,$W4=""),"Falta la fecha en que vence el balance",IF(AND($H4<>"Por confirmar",$H4<>"Cerrado",$AI4=0),"Consume 0 de cupo pero no está Por confirmar",""))))))))))
A5: 7-3 | B5: 7 | C5: Singsun | D5: Tracker | E5: 2 | F5: San Diego Sur 1, Santo Tomas Sur 3 | G5: Solenium | H5: Embarcado | J5: 46113 | K5: 46213 | M5: 46236 | N5: NSHEC260657564/565 | O5: Released | P5: 126166.93 | Q5: 0.1 | R5: =IF($A5="","",ROUND(P5*Q5,2)) | T5: Pagado | U5: 46094 | V5: =IF($A5="","",ROUND(P5-R5,2)) | W5: 46303 | X5: Pendiente | Z5: =IF($A5="","",IF(T5="Pagado",N(R5),0)+IF(X5="Pagado",N(V5),0)) | AA5: =IF($A5="","",ROUND(N(P5)-N(Z5),2)) | AB5: =IF($A5="","",SUMIF('OTROS COMPONENTES'!$A$4:$A$200,$A5,'OTROS COMPONENTES'!$D$4:$D$200)) | AC5: =IF($A5="","",SUMIF('OTROS COMPONENTES'!$A$4:$A$200,$A5,'OTROS COMPONENTES'!$E$4:$E$200)) | AD5: =IF($A5="","",ROUND(N(AB5)-N(AC5),2)) | AE5: =IF($A5="","",ROUND(N(P5)+N(AB5),2)) | AF5: =IF($A5="","",ROUND(N(Z5)+N(AC5),2)) | AG5: =IF($A5="","",ROUND(N(AA5)+N(AD5),2)) | AH5: =IF($A5="","",IF(OR($H5="Por confirmar",$H5="Cerrado"),"No","Sí")) | AI5: =IF($A5="","",IF(AH5="No",0,IF(RESUMEN!$B$4="Saldo por pagar al fabricante",AA5,IF(RESUMEN!$B$4="Monto completo del pedido",P5,IF(OR($H5="Embarcando",$H5="Embarcado"),N(AA5),N(P5)))))) | AJ5: =IF($A5="","",IF(COUNTIF($A$4:$A$200,$A5)>1,"ID_Pedido repetido",IF(N($P5)<=0,"Falta el costo del fabricante",IF($F5="","Falta el proyecto",IF($G5="","Falta el cliente",IF(AND($H5<>"Por confirmar",N($R5)>0,$T5=""),"Falta el estado del anticipo",IF(AND($H5<>"Por confirmar",N($V5)>0,$X5=""),"Falta el estado del balance",IF($E5>1,""&$E5&" equipos en una fila: pártela en una por proyecto",IF(AND($X5="Pendiente",N($V5)>0,$W5=""),"Falta la fecha en que vence el balance",IF(AND($H5<>"Por confirmar",$H5<>"Cerrado",$AI5=0),"Consume 0 de cupo pero no está Por confirmar",""))))))))))
A6: 7-4 | B6: 7 | C6: Singsun | D6: Tracker | E6: 2 | F6: San Diego Sur 2, Piojo 1 | G6: Solenium | H6: Embarcado | J6: 46113 | K6: 46217 | M6: 46240 | N6: NSHEC260657312/7946 | O6: Released | P6: 120836.19 | Q6: 0.1 | R6: =IF($A6="","",ROUND(P6*Q6,2)) | T6: Pagado | U6: 46094 | V6: =IF($A6="","",ROUND(P6-R6,2)) | W6: 46307 | X6: Pendiente | Z6: =IF($A6="","",IF(T6="Pagado",N(R6),0)+IF(X6="Pagado",N(V6),0)) | AA6: =IF($A6="","",ROUND(N(P6)-N(Z6),2)) | AB6: =IF($A6="","",SUMIF('OTROS COMPONENTES'!$A$4:$A$200,$A6,'OTROS COMPONENTES'!$D$4:$D$200)) | AC6: =IF($A6="","",SUMIF('OTROS COMPONENTES'!$A$4:$A$200,$A6,'OTROS COMPONENTES'!$E$4:$E$200)) | AD6: =IF($A6="","",ROUND(N(AB6)-N(AC6),2)) | AE6: =IF($A6="","",ROUND(N(P6)+N(AB6),2)) | AF6: =IF($A6="","",ROUND(N(Z6)+N(AC6),2)) | AG6: =IF($A6="","",ROUND(N(AA6)+N(AD6),2)) | AH6: =IF($A6="","",IF(OR($H6="Por confirmar",$H6="Cerrado"),"No","Sí")) | AI6: =IF($A6="","",IF(AH6="No",0,IF(RESUMEN!$B$4="Saldo por pagar al fabricante",AA6,IF(RESUMEN!$B$4="Monto completo del pedido",P6,IF(OR($H6="Embarcando",$H6="Embarcado"),N(AA6),N(P6)))))) | AJ6: =IF($A6="","",IF(COUNTIF($A$4:$A$200,$A6)>1,"ID_Pedido repetido",IF(N($P6)<=0,"Falta el costo del fabricante",IF($F6="","Falta el proyecto",IF($G6="","Falta el cliente",IF(AND($H6<>"Por confirmar",N($R6)>0,$T6=""),"Falta el estado del anticipo",IF(AND($H6<>"Por confirmar",N($V6)>0,$X6=""),"Falta el estado del balance",IF($E6>1,""&$E6&" equipos en una fila: pártela en una por proyecto",IF(AND($X6="Pendiente",N($V6)>0,$W6=""),"Falta la fecha en que vence el balance",IF(AND($H6<>"Por confirmar",$H6<>"Cerrado",$AI6=0),"Consume 0 de cupo pero no está Por confirmar",""))))))))))
A7: 7-5 | B7: 7 | C7: Singsun | D7: Tracker | E7: 1 | F7: Santo Tomas Sur 1 CFM (La Paz Junglar) | G7: Solenium | H7: Embarcando | J7: 46113 | K7: 46295 | M7: 46318 | O7: Pending | P7: 61744.43 | Q7: 0.1 | R7: =IF($A7="","",ROUND(P7*Q7,2)) | T7: Pagado | U7: 46094 | V7: =IF($A7="","",ROUND(P7-R7,2)) | X7: Pendiente | Z7: =IF($A7="","",IF(T7="Pagado",N(R7),0)+IF(X7="Pagado",N(V7),0)) | AA7: =IF($A7="","",ROUND(N(P7)-N(Z7),2)) | AB7: =IF($A7="","",SUMIF('OTROS COMPONENTES'!$A$4:$A$200,$A7,'OTROS COMPONENTES'!$D$4:$D$200)) | AC7: =IF($A7="","",SUMIF('OTROS COMPONENTES'!$A$4:$A$200,$A7,'OTROS COMPONENTES'!$E$4:$E$200)) | AD7: =IF($A7="","",ROUND(N(AB7)-N(AC7),2)) | AE7: =IF($A7="","",ROUND(N(P7)+N(AB7),2)) | AF7: =IF($A7="","",ROUND(N(Z7)+N(AC7),2)) | AG7: =IF($A7="","",ROUND(N(AA7)+N(AD7),2)) | AH7: =IF($A7="","",IF(OR($H7="Por confirmar",$H7="Cerrado"),"No","Sí")) | AI7: =IF($A7="","",IF(AH7="No",0,IF(RESUMEN!$B$4="Saldo por pagar al fabricante",AA7,IF(RESUMEN!$B$4="Monto completo del pedido",P7,IF(OR($H7="Embarcando",$H7="Embarcado"),N(AA7),N(P7)))))) | AJ7: =IF($A7="","",IF(COUNTIF($A$4:$A$200,$A7)>1,"ID_Pedido repetido",IF(N($P7)<=0,"Falta el costo del fabricante",IF($F7="","Falta el proyecto",IF($G7="","Falta el cliente",IF(AND($H7<>"Por confirmar",N($R7)>0,$T7=""),"Falta el estado del anticipo",IF(AND($H7<>"Por confirmar",N($V7)>0,$X7=""),"Falta el estado del balance",IF($E7>1,""&$E7&" equipos en una fila: pártela en una por proyecto",IF(AND($X7="Pendiente",N($V7)>0,$W7=""),"Falta la fecha en que vence el balance",IF(AND($H7<>"Por confirmar",$H7<>"Cerrado",$AI7=0),"Consume 0 de cupo pero no está Por confirmar",""))))))))))
A8: 7-6 | B8: 7 | C8: Singsun | D8: Tracker | E8: 1 | F8: Paratebueno (Piojo 2) | G8: Solenium | H8: Embarcando | J8: 46113 | O8: Pending | P8: 60849.86 | Q8: 0.1 | R8: =IF($A8="","",ROUND(P8*Q8,2)) | T8: Pagado | U8: 46094 | V8: =IF($A8="","",ROUND(P8-R8,2)) | X8: Pendiente | Z8: =IF($A8="","",IF(T8="Pagado",N(R8),0)+IF(X8="Pagado",N(V8),0)) | AA8: =IF($A8="","",ROUND(N(P8)-N(Z8),2)) | AB8: =IF($A8="","",SUMIF('OTROS COMPONENTES'!$A$4:$A$200,$A8,'OTROS COMPONENTES'!$D$4:$D$200)) | AC8: =IF($A8="","",SUMIF('OTROS COMPONENTES'!$A$4:$A$200,$A8,'OTROS COMPONENTES'!$E$4:$E$200)) | AD8: =IF($A8="","",ROUND(N(AB8)-N(AC8),2)) | AE8: =IF($A8="","",ROUND(N(P8)+N(AB8),2)) | AF8: =IF($A8="","",ROUND(N(Z8)+N(AC8),2)) | AG8: =IF($A8="","",ROUND(N(AA8)+N(AD8),2)) | AH8: =IF($A8="","",IF(OR($H8="Por confirmar",$H8="Cerrado"),"No","Sí")) | AI8: =IF($A8="","",IF(AH8="No",0,IF(RESUMEN!$B$4="Saldo por pagar al fabricante",AA8,IF(RESUMEN!$B$4="Monto completo del pedido",P8,IF(OR($H8="Embarcando",$H8="Embarcado"),N(AA8),N(P8)))))) | AJ8: =IF($A8="","",IF(COUNTIF($A$4:$A$200,$A8)>1,"ID_Pedido repetido",IF(N($P8)<=0,"Falta el costo del fabricante",IF($F8="","Falta el proyecto",IF($G8="","Falta el cliente",IF(AND($H8<>"Por confirmar",N($R8)>0,$T8=""),"Falta el estado del anticipo",IF(AND($H8<>"Por confirmar",N($V8)>0,$X8=""),"Falta el estado del balance",IF($E8>1,""&$E8&" equipos en una fila: pártela en una por proyecto",IF(AND($X8="Pendiente",N($V8)>0,$W8=""),"Falta la fecha en que vence el balance",IF(AND($H8<>"Por confirmar",$H8<>"Cerrado",$AI8=0),"Consume 0 de cupo pero no está Por confirmar",""))))))))))
A9: 7-7 | B9: 7 | C9: Singsun | D9: Tracker | E9: 1 | F9: Paratebueno 2 (Piojo 3) | G9: Solenium | H9: Embarcando | J9: 46113 | O9: Pending | P9: 60849.86 | Q9: 0.1 | R9: =IF($A9="","",ROUND(P9*Q9,2)) | T9: Pagado | U9: 46094 | V9: =IF($A9="","",ROUND(P9-R9,2)) | X9: Pendiente | Z9: =IF($A9="","",IF(T9="Pagado",N(R9),0)+IF(X9="Pagado",N(V9),0)) | AA9: =IF($A9="","",ROUND(N(P9)-N(Z9),2)) | AB9: =IF($A9="","",SUMIF('OTROS COMPONENTES'!$A$4:$A$200,$A9,'OTROS COMPONENTES'!$D$4:$D$200)) | AC9: =IF($A9="","",SUMIF('OTROS COMPONENTES'!$A$4:$A$200,$A9,'OTROS COMPONENTES'!$E$4:$E$200)) | AD9: =IF($A9="","",ROUND(N(AB9)-N(AC9),2)) | AE9: =IF($A9="","",ROUND(N(P9)+N(AB9),2)) | AF9: =IF($A9="","",ROUND(N(Z9)+N(AC9),2)) | AG9: =IF($A9="","",ROUND(N(AA9)+N(AD9),2)) | AH9: =IF($A9="","",IF(OR($H9="Por confirmar",$H9="Cerrado"),"No","Sí")) | AI9: =IF($A9="","",IF(AH9="No",0,IF(RESUMEN!$B$4="Saldo por pagar al fabricante",AA9,IF(RESUMEN!$B$4="Monto completo del pedido",P9,IF(OR($H9="Embarcando",$H9="Embarcado"),N(AA9),N(P9)))))) | AJ9: =IF($A9="","",IF(COUNTIF($A$4:$A$200,$A9)>1,"ID_Pedido repetido",IF(N($P9)<=0,"Falta el costo del fabricante",IF($F9="","Falta el proyecto",IF($G9="","Falta el cliente",IF(AND($H9<>"Por confirmar",N($R9)>0,$T9=""),"Falta el estado del anticipo",IF(AND($H9<>"Por confirmar",N($V9)>0,$X9=""),"Falta el estado del balance",IF($E9>1,""&$E9&" equipos en una fila: pártela en una por proyecto",IF(AND($X9="Pendiente",N($V9)>0,$W9=""),"Falta la fecha en que vence el balance",IF(AND($H9<>"Por confirmar",$H9<>"Cerrado",$AI9=0),"Consume 0 de cupo pero no está Por confirmar",""))))))))))
A10: 7-8 | B10: 7 | C10: Singsun | D10: Tracker | E10: 1 | F10: Paratebueno 2 (Piojo 3) | G10: Solenium | H10: Embarque reservado | J10: 46113 | O10: Pending | P10: 55127.31 | Q10: 0.1 | R10: =IF($A10="","",ROUND(P10*Q10,2)) | T10: Pagado | U10: 46094 | V10: =IF($A10="","",ROUND(P10-R10,2)) | X10: Pendiente | Z10: =IF($A10="","",IF(T10="Pagado",N(R10),0)+IF(X10="Pagado",N(V10),0)) | AA10: =IF($A10="","",ROUND(N(P10)-N(Z10),2)) | AB10: =IF($A10="","",SUMIF('OTROS COMPONENTES'!$A$4:$A$200,$A10,'OTROS COMPONENTES'!$D$4:$D$200)) | AC10: =IF($A10="","",SUMIF('OTROS COMPONENTES'!$A$4:$A$200,$A10,'OTROS COMPONENTES'!$E$4:$E$200)) | AD10: =IF($A10="","",ROUND(N(AB10)-N(AC10),2)) | AE10: =IF($A10="","",ROUND(N(P10)+N(AB10),2)) | AF10: =IF($A10="","",ROUND(N(Z10)+N(AC10),2)) | AG10: =IF($A10="","",ROUND(N(AA10)+N(AD10),2)) | AH10: =IF($A10="","",IF(OR($H10="Por confirmar",$H10="Cerrado"),"No","Sí")) | AI10: =IF($A10="","",IF(AH10="No",0,IF(RESUMEN!$B$4="Saldo por pagar al fabricante",AA10,IF(RESUMEN!$B$4="Monto completo del pedido",P10,IF(OR($H10="Embarcando",$H10="Embarcado"),N(AA10),N(P10)))))) | AJ10: =IF($A10="","",IF(COUNTIF($A$4:$A$200,$A10)>1,"ID_Pedido repetido",IF(N($P10)<=0,"Falta el costo del fabricante",IF($F10="","Falta el proyecto",IF($G10="","Falta el cliente",IF(AND($H10<>"Por confirmar",N($R10)>0,$T10=""),"Falta el estado del anticipo",IF(AND($H10<>"Por confirmar",N($V10)>0,$X10=""),"Falta el estado del balance",IF($E10>1,""&$E10&" equipos en una fila: pártela en una por proyecto",IF(AND($X10="Pendiente",N($V10)>0,$W10=""),"Falta la fecha en que vence el balance",IF(AND($H10<>"Por confirmar",$H10<>"Cerrado",$AI10=0),"Consume 0 de cupo pero no está Por confirmar",""))))))))))
A11: 7-9 | B11: 7 | C11: Singsun | D11: Tracker | E11: 1 | F11: (El Paseo) | G11: Solenium | H11: Embarque reservado | J11: 46113 | O11: Pending | P11: 55127.31 | Q11: 0.1 | R11: =IF($A11="","",ROUND(P11*Q11,2)) | T11: Pagado | U11: 46094 | V11: =IF($A11="","",ROUND(P11-R11,2)) | X11: Pendiente | Z11: =IF($A11="","",IF(T11="Pagado",N(R11),0)+IF(X11="Pagado",N(V11),0)) | AA11: =IF($A11="","",ROUND(N(P11)-N(Z11),2)) | AB11: =IF($A11="","",SUMIF('OTROS COMPONENTES'!$A$4:$A$200,$A11,'OTROS COMPONENTES'!$D$4:$D$200)) | AC11: =IF($A11="","",SUMIF('OTROS COMPONENTES'!$A$4:$A$200,$A11,'OTROS COMPONENTES'!$E$4:$E$200)) | AD11: =IF($A11="","",ROUND(N(AB11)-N(AC11),2)) | AE11: =IF($A11="","",ROUND(N(P11)+N(AB11),2)) | AF11: =IF($A11="","",ROUND(N(Z11)+N(AC11),2)) | AG11: =IF($A11="","",ROUND(N(AA11)+N(AD11),2)) | AH11: =IF($A11="","",IF(OR($H11="Por confirmar",$H11="Cerrado"),"No","Sí")) | AI11: =IF($A11="","",IF(AH11="No",0,IF(RESUMEN!$B$4="Saldo por pagar al fabricante",AA11,IF(RESUMEN!$B$4="Monto completo del pedido",P11,IF(OR($H11="Embarcando",$H11="Embarcado"),N(AA11),N(P11)))))) | AJ11: =IF($A11="","",IF(COUNTIF($A$4:$A$200,$A11)>1,"ID_Pedido repetido",IF(N($P11)<=0,"Falta el costo del fabricante",IF($F11="","Falta el proyecto",IF($G11="","Falta el cliente",IF(AND($H11<>"Por confirmar",N($R11)>0,$T11=""),"Falta el estado del anticipo",IF(AND($H11<>"Por confirmar",N($V11)>0,$X11=""),"Falta el estado del balance",IF($E11>1,""&$E11&" equipos en una fila: pártela en una por proyecto",IF(AND($X11="Pendiente",N($V11)>0,$W11=""),"Falta la fecha en que vence el balance",IF(AND($H11<>"Por confirmar",$H11<>"Cerrado",$AI11=0),"Consume 0 de cupo pero no está Por confirmar",""))))))))))
A12: 9-1 | B12: 9 | C12: Singsun | D12: Tracker | E12: 1 | F12: Giron Sur 2 | G12: Solenium | H12: En producción | J12: 46300 | O12: Pending | P12: 56933.17 | Q12: 0.0943 | R12: =IF($A12="","",ROUND(P12*Q12,2)) | T12: Pagado | U12: 46176 | V12: =IF($A12="","",ROUND(P12-R12,2)) | X12: Pendiente | Z12: =IF($A12="","",IF(T12="Pagado",N(R12),0)+IF(X12="Pagado",N(V12),0)) | AA12: =IF($A12="","",ROUND(N(P12)-N(Z12),2)) | AB12: =IF($A12="","",SUMIF('OTROS COMPONENTES'!$A$4:$A$200,$A12,'OTROS COMPONENTES'!$D$4:$D$200)) | AC12: =IF($A12="","",SUMIF('OTROS COMPONENTES'!$A$4:$A$200,$A12,'OTROS COMPONENTES'!$E$4:$E$200)) | AD12: =IF($A12="","",ROUND(N(AB12)-N(AC12),2)) | AE12: =IF($A12="","",ROUND(N(P12)+N(AB12),2)) | AF12: =IF($A12="","",ROUND(N(Z12)+N(AC12),2)) | AG12: =IF($A12="","",ROUND(N(AA12)+N(AD12),2)) | AH12: =IF($A12="","",IF(OR($H12="Por confirmar",$H12="Cerrado"),"No","Sí")) | AI12: =IF($A12="","",IF(AH12="No",0,IF(RESUMEN!$B$4="Saldo por pagar al fabricante",AA12,IF(RESUMEN!$B$4="Monto completo del pedido",P12,IF(OR($H12="Embarcando",$H12="Embarcado"),N(AA12),N(P12)))))) | AJ12: =IF($A12="","",IF(COUNTIF($A$4:$A$200,$A12)>1,"ID_Pedido repetido",IF(N($P12)<=0,"Falta el costo del fabricante",IF($F12="","Falta el proyecto",IF($G12="","Falta el cliente",IF(AND($H12<>"Por confirmar",N($R12)>0,$T12=""),"Falta el estado del anticipo",IF(AND($H12<>"Por confirmar",N($V12)>0,$X12=""),"Falta el estado del balance",IF($E12>1,""&$E12&" equipos en una fila: pártela en una por proyecto",IF(AND($X12="Pendiente",N($V12)>0,$W12=""),"Falta la fecha en que vence el balance",IF(AND($H12<>"Por confirmar",$H12<>"Cerrado",$AI12=0),"Consume 0 de cupo pero no está Por confirmar","")))))))))) | AK12: Estado de pago deducido: venía en blanco en el detailed
A13: 9-2 | B13: 9 | C13: Singsun | D13: Tracker | E13: 1 | F13: Confines de Occidente 2 | G13: Solenium | H13: Embarcando | J13: 46293 | O13: Pending | P13: 71719.75 | Q13: 0.1 | R13: =IF($A13="","",ROUND(P13*Q13,2)) | T13: Pagado | U13: 46176 | V13: =IF($A13="","",ROUND(P13-R13,2)) | X13: Pendiente | Z13: =IF($A13="","",IF(T13="Pagado",N(R13),0)+IF(X13="Pagado",N(V13),0)) | AA13: =IF($A13="","",ROUND(N(P13)-N(Z13),2)) | AB13: =IF($A13="","",SUMIF('OTROS COMPONENTES'!$A$4:$A$200,$A13,'OTROS COMPONENTES'!$D$4:$D$200)) | AC13: =IF($A13="","",SUMIF('OTROS COMPONENTES'!$A$4:$A$200,$A13,'OTROS COMPONENTES'!$E$4:$E$200)) | AD13: =IF($A13="","",ROUND(N(AB13)-N(AC13),2)) | AE13: =IF($A13="","",ROUND(N(P13)+N(AB13),2)) | AF13: =IF($A13="","",ROUND(N(Z13)+N(AC13),2)) | AG13: =IF($A13="","",ROUND(N(AA13)+N(AD13),2)) | AH13: =IF($A13="","",IF(OR($H13="Por confirmar",$H13="Cerrado"),"No","Sí")) | AI13: =IF($A13="","",IF(AH13="No",0,IF(RESUMEN!$B$4="Saldo por pagar al fabricante",AA13,IF(RESUMEN!$B$4="Monto completo del pedido",P13,IF(OR($H13="Embarcando",$H13="Embarcado"),N(AA13),N(P13)))))) | AJ13: =IF($A13="","",IF(COUNTIF($A$4:$A$200,$A13)>1,"ID_Pedido repetido",IF(N($P13)<=0,"Falta el costo del fabricante",IF($F13="","Falta el proyecto",IF($G13="","Falta el cliente",IF(AND($H13<>"Por confirmar",N($R13)>0,$T13=""),"Falta el estado del anticipo",IF(AND($H13<>"Por confirmar",N($V13)>0,$X13=""),"Falta el estado del balance",IF($E13>1,""&$E13&" equipos en una fila: pártela en una por proyecto",IF(AND($X13="Pendiente",N($V13)>0,$W13=""),"Falta la fecha en que vence el balance",IF(AND($H13<>"Por confirmar",$H13<>"Cerrado",$AI13=0),"Consume 0 de cupo pero no está Por confirmar","")))))))))) | AK13: Estado de pago deducido: venía en blanco en el detailed
A14: 9-3 | B14: 9 | C14: Singsun | D14: Tracker | E14: 1 | F14: Agustin Codazzi 4 -> Galapa 2 | G14: Solenium | H14: En producción | J14: 46310 | O14: Pending | P14: 66985.63 | Q14: 0.1 | R14: =IF($A14="","",ROUND(P14*Q14,2)) | T14: Pagado | U14: 46176 | V14: =IF($A14="","",ROUND(P14-R14,2)) | X14: Pendiente | Z14: =IF($A14="","",IF(T14="Pagado",N(R14),0)+IF(X14="Pagado",N(V14),0)) | AA14: =IF($A14="","",ROUND(N(P14)-N(Z14),2)) | AB14: =IF($A14="","",SUMIF('OTROS COMPONENTES'!$A$4:$A$200,$A14,'OTROS COMPONENTES'!$D$4:$D$200)) | AC14: =IF($A14="","",SUMIF('OTROS COMPONENTES'!$A$4:$A$200,$A14,'OTROS COMPONENTES'!$E$4:$E$200)) | AD14: =IF($A14="","",ROUND(N(AB14)-N(AC14),2)) | AE14: =IF($A14="","",ROUND(N(P14)+N(AB14),2)) | AF14: =IF($A14="","",ROUND(N(Z14)+N(AC14),2)) | AG14: =IF($A14="","",ROUND(N(AA14)+N(AD14),2)) | AH14: =IF($A14="","",IF(OR($H14="Por confirmar",$H14="Cerrado"),"No","Sí")) | AI14: =IF($A14="","",IF(AH14="No",0,IF(RESUMEN!$B$4="Saldo por pagar al fabricante",AA14,IF(RESUMEN!$B$4="Monto completo del pedido",P14,IF(OR($H14="Embarcando",$H14="Embarcado"),N(AA14),N(P14)))))) | AJ14: =IF($A14="","",IF(COUNTIF($A$4:$A$200,$A14)>1,"ID_Pedido repetido",IF(N($P14)<=0,"Falta el costo del fabricante",IF($F14="","Falta el proyecto",IF($G14="","Falta el cliente",IF(AND($H14<>"Por confirmar",N($R14)>0,$T14=""),"Falta el estado del anticipo",IF(AND($H14<>"Por confirmar",N($V14)>0,$X14=""),"Falta el estado del balance",IF($E14>1,""&$E14&" equipos en una fila: pártela en una por proyecto",IF(AND($X14="Pendiente",N($V14)>0,$W14=""),"Falta la fecha en que vence el balance",IF(AND($H14<>"Por confirmar",$H14<>"Cerrado",$AI14=0),"Consume 0 de cupo pero no está Por confirmar",""))))))))))
A15: 9-5 | B15: 9 | C15: Singsun | D15: Tracker | E15: 1 | F15: Tunja | G15: Solenium | H15: En producción | J15: 46311 | O15: Pending | P15: 59726.2 | Q15: 0.0952 | R15: =IF($A15="","",ROUND(P15*Q15,2)) | T15: Pagado | U15: 46176 | V15: =IF($A15="","",ROUND(P15-R15,2)) | X15: Pendiente | Z15: =IF($A15="","",IF(T15="Pagado",N(R15),0)+IF(X15="Pagado",N(V15),0)) | AA15: =IF($A15="","",ROUND(N(P15)-N(Z15),2)) | AB15: =IF($A15="","",SUMIF('OTROS COMPONENTES'!$A$4:$A$200,$A15,'OTROS COMPONENTES'!$D$4:$D$200)) | AC15: =IF($A15="","",SUMIF('OTROS COMPONENTES'!$A$4:$A$200,$A15,'OTROS COMPONENTES'!$E$4:$E$200)) | AD15: =IF($A15="","",ROUND(N(AB15)-N(AC15),2)) | AE15: =IF($A15="","",ROUND(N(P15)+N(AB15),2)) | AF15: =IF($A15="","",ROUND(N(Z15)+N(AC15),2)) | AG15: =IF($A15="","",ROUND(N(AA15)+N(AD15),2)) | AH15: =IF($A15="","",IF(OR($H15="Por confirmar",$H15="Cerrado"),"No","Sí")) | AI15: =IF($A15="","",IF(AH15="No",0,IF(RESUMEN!$B$4="Saldo por pagar al fabricante",AA15,IF(RESUMEN!$B$4="Monto completo del pedido",P15,IF(OR($H15="Embarcando",$H15="Embarcado"),N(AA15),N(P15)))))) | AJ15: =IF($A15="","",IF(COUNTIF($A$4:$A$200,$A15)>1,"ID_Pedido repetido",IF(N($P15)<=0,"Falta el costo del fabricante",IF($F15="","Falta el proyecto",IF($G15="","Falta el cliente",IF(AND($H15<>"Por confirmar",N($R15)>0,$T15=""),"Falta el estado del anticipo",IF(AND($H15<>"Por confirmar",N($V15)>0,$X15=""),"Falta el estado del balance",IF($E15>1,""&$E15&" equipos en una fila: pártela en una por proyecto",IF(AND($X15="Pendiente",N($V15)>0,$W15=""),"Falta la fecha en que vence el balance",IF(AND($H15<>"Por confirmar",$H15<>"Cerrado",$AI15=0),"Consume 0 de cupo pero no está Por confirmar",""))))))))))
A16: 9-6 | B16: 9 | C16: Singsun | D16: Tracker | E16: 1 | F16: Curumani 3 | G16: Solenium | H16: En producción | J16: 46307 | O16: Pending | P16: 57149.96 | Q16: 0.1 | R16: =IF($A16="","",ROUND(P16*Q16,2)) | T16: Pagado | U16: 46176 | V16: =IF($A16="","",ROUND(P16-R16,2)) | X16: Pendiente | Z16: =IF($A16="","",IF(T16="Pagado",N(R16),0)+IF(X16="Pagado",N(V16),0)) | AA16: =IF($A16="","",ROUND(N(P16)-N(Z16),2)) | AB16: =IF($A16="","",SUMIF('OTROS COMPONENTES'!$A$4:$A$200,$A16,'OTROS COMPONENTES'!$D$4:$D$200)) | AC16: =IF($A16="","",SUMIF('OTROS COMPONENTES'!$A$4:$A$200,$A16,'OTROS COMPONENTES'!$E$4:$E$200)) | AD16: =IF($A16="","",ROUND(N(AB16)-N(AC16),2)) | AE16: =IF($A16="","",ROUND(N(P16)+N(AB16),2)) | AF16: =IF($A16="","",ROUND(N(Z16)+N(AC16),2)) | AG16: =IF($A16="","",ROUND(N(AA16)+N(AD16),2)) | AH16: =IF($A16="","",IF(OR($H16="Por confirmar",$H16="Cerrado"),"No","Sí")) | AI16: =IF($A16="","",IF(AH16="No",0,IF(RESUMEN!$B$4="Saldo por pagar al fabricante",AA16,IF(RESUMEN!$B$4="Monto completo del pedido",P16,IF(OR($H16="Embarcando",$H16="Embarcado"),N(AA16),N(P16)))))) | AJ16: =IF($A16="","",IF(COUNTIF($A$4:$A$200,$A16)>1,"ID_Pedido repetido",IF(N($P16)<=0,"Falta el costo del fabricante",IF($F16="","Falta el proyecto",IF($G16="","Falta el cliente",IF(AND($H16<>"Por confirmar",N($R16)>0,$T16=""),"Falta el estado del anticipo",IF(AND($H16<>"Por confirmar",N($V16)>0,$X16=""),"Falta el estado del balance",IF($E16>1,""&$E16&" equipos en una fila: pártela en una por proyecto",IF(AND($X16="Pendiente",N($V16)>0,$W16=""),"Falta la fecha en que vence el balance",IF(AND($H16<>"Por confirmar",$H16<>"Cerrado",$AI16=0),"Consume 0 de cupo pero no está Por confirmar",""))))))))))
A17: 9-7 | B17: 9 | C17: Singsun | D17: Tracker | E17: 1 | G17: Solenium | H17: En producción | J17: 46237 | K17: 46270 | M17: 46292 | O17: Pending | P17: 20988.45 | Q17: 0.1 | R17: =IF($A17="","",ROUND(P17*Q17,2)) | T17: Pagado | U17: 46176 | V17: =IF($A17="","",ROUND(P17-R17,2)) | X17: Pendiente | Z17: =IF($A17="","",IF(T17="Pagado",N(R17),0)+IF(X17="Pagado",N(V17),0)) | AA17: =IF($A17="","",ROUND(N(P17)-N(Z17),2)) | AB17: =IF($A17="","",SUMIF('OTROS COMPONENTES'!$A$4:$A$200,$A17,'OTROS COMPONENTES'!$D$4:$D$200)) | AC17: =IF($A17="","",SUMIF('OTROS COMPONENTES'!$A$4:$A$200,$A17,'OTROS COMPONENTES'!$E$4:$E$200)) | AD17: =IF($A17="","",ROUND(N(AB17)-N(AC17),2)) | AE17: =IF($A17="","",ROUND(N(P17)+N(AB17),2)) | AF17: =IF($A17="","",ROUND(N(Z17)+N(AC17),2)) | AG17: =IF($A17="","",ROUND(N(AA17)+N(AD17),2)) | AH17: =IF($A17="","",IF(OR($H17="Por confirmar",$H17="Cerrado"),"No","Sí")) | AI17: =IF($A17="","",IF(AH17="No",0,IF(RESUMEN!$B$4="Saldo por pagar al fabricante",AA17,IF(RESUMEN!$B$4="Monto completo del pedido",P17,IF(OR($H17="Embarcando",$H17="Embarcado"),N(AA17),N(P17)))))) | AJ17: =IF($A17="","",IF(COUNTIF($A$4:$A$200,$A17)>1,"ID_Pedido repetido",IF(N($P17)<=0,"Falta el costo del fabricante",IF($F17="","Falta el proyecto",IF($G17="","Falta el cliente",IF(AND($H17<>"Por confirmar",N($R17)>0,$T17=""),"Falta el estado del anticipo",IF(AND($H17<>"Por confirmar",N($V17)>0,$X17=""),"Falta el estado del balance",IF($E17>1,""&$E17&" equipos en una fila: pártela en una por proyecto",IF(AND($X17="Pendiente",N($V17)>0,$W17=""),"Falta la fecha en que vence el balance",IF(AND($H17<>"Por confirmar",$H17<>"Cerrado",$AI17=0),"Consume 0 de cupo pero no está Por confirmar",""))))))))))
A18: 9-8 | B18: 9 | C18: Singsun | D18: Tracker | E18: 1 | G18: Solenium | H18: En producción | J18: 46310 | O18: Pending | P18: 13554.6 | Q18: 0.1 | R18: =IF($A18="","",ROUND(P18*Q18,2)) | T18: Pagado | U18: 46176 | V18: =IF($A18="","",ROUND(P18-R18,2)) | X18: Pendiente | Z18: =IF($A18="","",IF(T18="Pagado",N(R18),0)+IF(X18="Pagado",N(V18),0)) | AA18: =IF($A18="","",ROUND(N(P18)-N(Z18),2)) | AB18: =IF($A18="","",SUMIF('OTROS COMPONENTES'!$A$4:$A$200,$A18,'OTROS COMPONENTES'!$D$4:$D$200)) | AC18: =IF($A18="","",SUMIF('OTROS COMPONENTES'!$A$4:$A$200,$A18,'OTROS COMPONENTES'!$E$4:$E$200)) | AD18: =IF($A18="","",ROUND(N(AB18)-N(AC18),2)) | AE18: =IF($A18="","",ROUND(N(P18)+N(AB18),2)) | AF18: =IF($A18="","",ROUND(N(Z18)+N(AC18),2)) | AG18: =IF($A18="","",ROUND(N(AA18)+N(AD18),2)) | AH18: =IF($A18="","",IF(OR($H18="Por confirmar",$H18="Cerrado"),"No","Sí")) | AI18: =IF($A18="","",IF(AH18="No",0,IF(RESUMEN!$B$4="Saldo por pagar al fabricante",AA18,IF(RESUMEN!$B$4="Monto completo del pedido",P18,IF(OR($H18="Embarcando",$H18="Embarcado"),N(AA18),N(P18)))))) | AJ18: =IF($A18="","",IF(COUNTIF($A$4:$A$200,$A18)>1,"ID_Pedido repetido",IF(N($P18)<=0,"Falta el costo del fabricante",IF($F18="","Falta el proyecto",IF($G18="","Falta el cliente",IF(AND($H18<>"Por confirmar",N($R18)>0,$T18=""),"Falta el estado del anticipo",IF(AND($H18<>"Por confirmar",N($V18)>0,$X18=""),"Falta el estado del balance",IF($E18>1,""&$E18&" equipos en una fila: pártela en una por proyecto",IF(AND($X18="Pendiente",N($V18)>0,$W18=""),"Falta la fecha en que vence el balance",IF(AND($H18<>"Por confirmar",$H18<>"Cerrado",$AI18=0),"Consume 0 de cupo pero no está Por confirmar",""))))))))))
A19: 10 | B19: 10 | C19: Singsun | D19: Tracker | E19: 2 | F19: Mariangola | H19: En producción | J19: 46239 | K19: 46254 | M19: 46294 | O19: Pending | P19: 123843.08 | Q19: 0.1 | R19: =IF($A19="","",ROUND(P19*Q19,2)) | T19: Pagado | U19: 46176 | V19: =IF($A19="","",ROUND(P19-R19,2)) | X19: Pendiente | Z19: =IF($A19="","",IF(T19="Pagado",N(R19),0)+IF(X19="Pagado",N(V19),0)) | AA19: =IF($A19="","",ROUND(N(P19)-N(Z19),2)) | AB19: =IF($A19="","",SUMIF('OTROS COMPONENTES'!$A$4:$A$200,$A19,'OTROS COMPONENTES'!$D$4:$D$200)) | AC19: =IF($A19="","",SUMIF('OTROS COMPONENTES'!$A$4:$A$200,$A19,'OTROS COMPONENTES'!$E$4:$E$200)) | AD19: =IF($A19="","",ROUND(N(AB19)-N(AC19),2)) | AE19: =IF($A19="","",ROUND(N(P19)+N(AB19),2)) | AF19: =IF($A19="","",ROUND(N(Z19)+N(AC19),2)) | AG19: =IF($A19="","",ROUND(N(AA19)+N(AD19),2)) | AH19: =IF($A19="","",IF(OR($H19="Por confirmar",$H19="Cerrado"),"No","Sí")) | AI19: =IF($A19="","",IF(AH19="No",0,IF(RESUMEN!$B$4="Saldo por pagar al fabricante",AA19,IF(RESUMEN!$B$4="Monto completo del pedido",P19,IF(OR($H19="Embarcando",$H19="Embarcado"),N(AA19),N(P19)))))) | AJ19: =IF($A19="","",IF(COUNTIF($A$4:$A$200,$A19)>1,"ID_Pedido repetido",IF(N($P19)<=0,"Falta el costo del fabricante",IF($F19="","Falta el proyecto",IF($G19="","Falta el cliente",IF(AND($H19<>"Por confirmar",N($R19)>0,$T19=""),"Falta el estado del anticipo",IF(AND($H19<>"Por confirmar",N($V19)>0,$X19=""),"Falta el estado del balance",IF($E19>1,""&$E19&" equipos en una fila: pártela en una por proyecto",IF(AND($X19="Pendiente",N($V19)>0,$W19=""),"Falta la fecha en que vence el balance",IF(AND($H19<>"Por confirmar",$H19<>"Cerrado",$AI19=0),"Consume 0 de cupo pero no está Por confirmar",""))))))))))
A20: 11-1 | B20: 11 | C20: Singsun | D20: Tracker | E20: 3 | F20: Santo Tomas Sur 1/2/3 (1P) -> Enexa | G20: Solenium | H20: En producción | J20: 46310 | O20: Pending | P20: 212149.08 | Q20: 0.0667 | R20: =IF($A20="","",ROUND(P20*Q20,2)) | T20: Pagado | U20: 46227 | V20: =IF($A20="","",ROUND(P20-R20,2)) | X20: Pendiente | Z20: =IF($A20="","",IF(T20="Pagado",N(R20),0)+IF(X20="Pagado",N(V20),0)) | AA20: =IF($A20="","",ROUND(N(P20)-N(Z20),2)) | AB20: =IF($A20="","",SUMIF('OTROS COMPONENTES'!$A$4:$A$200,$A20,'OTROS COMPONENTES'!$D$4:$D$200)) | AC20: =IF($A20="","",SUMIF('OTROS COMPONENTES'!$A$4:$A$200,$A20,'OTROS COMPONENTES'!$E$4:$E$200)) | AD20: =IF($A20="","",ROUND(N(AB20)-N(AC20),2)) | AE20: =IF($A20="","",ROUND(N(P20)+N(AB20),2)) | AF20: =IF($A20="","",ROUND(N(Z20)+N(AC20),2)) | AG20: =IF($A20="","",ROUND(N(AA20)+N(AD20),2)) | AH20: =IF($A20="","",IF(OR($H20="Por confirmar",$H20="Cerrado"),"No","Sí")) | AI20: =IF($A20="","",IF(AH20="No",0,IF(RESUMEN!$B$4="Saldo por pagar al fabricante",AA20,IF(RESUMEN!$B$4="Monto completo del pedido",P20,IF(OR($H20="Embarcando",$H20="Embarcado"),N(AA20),N(P20)))))) | AJ20: =IF($A20="","",IF(COUNTIF($A$4:$A$200,$A20)>1,"ID_Pedido repetido",IF(N($P20)<=0,"Falta el costo del fabricante",IF($F20="","Falta el proyecto",IF($G20="","Falta el cliente",IF(AND($H20<>"Por confirmar",N($R20)>0,$T20=""),"Falta el estado del anticipo",IF(AND($H20<>"Por confirmar",N($V20)>0,$X20=""),"Falta el estado del balance",IF($E20>1,""&$E20&" equipos en una fila: pártela en una por proyecto",IF(AND($X20="Pendiente",N($V20)>0,$W20=""),"Falta la fecha en que vence el balance",IF(AND($H20<>"Por confirmar",$H20<>"Cerrado",$AI20=0),"Consume 0 de cupo pero no está Por confirmar",""))))))))))
A21: 11-2 | B21: 11 | C21: Singsun | D21: Tracker | E21: 1 | G21: Solenium | H21: En producción | J21: 46237 | K21: 46257 | M21: 46279 | O21: Pending | P21: 3290 | Q21: 1 | R21: =IF($A21="","",ROUND(P21*Q21,2)) | T21: Pagado | U21: 46225 | V21: =IF($A21="","",ROUND(P21-R21,2)) | Z21: =IF($A21="","",IF(T21="Pagado",N(R21),0)+IF(X21="Pagado",N(V21),0)) | AA21: =IF($A21="","",ROUND(N(P21)-N(Z21),2)) | AB21: =IF($A21="","",SUMIF('OTROS COMPONENTES'!$A$4:$A$200,$A21,'OTROS COMPONENTES'!$D$4:$D$200)) | AC21: =IF($A21="","",SUMIF('OTROS COMPONENTES'!$A$4:$A$200,$A21,'OTROS COMPONENTES'!$E$4:$E$200)) | AD21: =IF($A21="","",ROUND(N(AB21)-N(AC21),2)) | AE21: =IF($A21="","",ROUND(N(P21)+N(AB21),2)) | AF21: =IF($A21="","",ROUND(N(Z21)+N(AC21),2)) | AG21: =IF($A21="","",ROUND(N(AA21)+N(AD21),2)) | AH21: =IF($A21="","",IF(OR($H21="Por confirmar",$H21="Cerrado"),"No","Sí")) | AI21: =IF($A21="","",IF(AH21="No",0,IF(RESUMEN!$B$4="Saldo por pagar al fabricante",AA21,IF(RESUMEN!$B$4="Monto completo del pedido",P21,IF(OR($H21="Embarcando",$H21="Embarcado"),N(AA21),N(P21)))))) | AJ21: =IF($A21="","",IF(COUNTIF($A$4:$A$200,$A21)>1,"ID_Pedido repetido",IF(N($P21)<=0,"Falta el costo del fabricante",IF($F21="","Falta el proyecto",IF($G21="","Falta el cliente",IF(AND($H21<>"Por confirmar",N($R21)>0,$T21=""),"Falta el estado del anticipo",IF(AND($H21<>"Por confirmar",N($V21)>0,$X21=""),"Falta el estado del balance",IF($E21>1,""&$E21&" equipos en una fila: pártela en una por proyecto",IF(AND($X21="Pendiente",N($V21)>0,$W21=""),"Falta la fecha en que vence el balance",IF(AND($H21<>"Por confirmar",$H21<>"Cerrado",$AI21=0),"Consume 0 de cupo pero no está Por confirmar",""))))))))))
A22: 11-3 | B22: 11 | C22: Singsun | D22: Tracker | E22: 1 | F22: Molinos 3 (1P) | G22: Solenium | H22: En producción | J22: 46310 | O22: Pending | P22: 63801 | Q22: 0.1 | R22: =IF($A22="","",ROUND(P22*Q22,2)) | T22: Pagado | U22: 46227 | V22: =IF($A22="","",ROUND(P22-R22,2)) | X22: Pendiente | Z22: =IF($A22="","",IF(T22="Pagado",N(R22),0)+IF(X22="Pagado",N(V22),0)) | AA22: =IF($A22="","",ROUND(N(P22)-N(Z22),2)) | AB22: =IF($A22="","",SUMIF('OTROS COMPONENTES'!$A$4:$A$200,$A22,'OTROS COMPONENTES'!$D$4:$D$200)) | AC22: =IF($A22="","",SUMIF('OTROS COMPONENTES'!$A$4:$A$200,$A22,'OTROS COMPONENTES'!$E$4:$E$200)) | AD22: =IF($A22="","",ROUND(N(AB22)-N(AC22),2)) | AE22: =IF($A22="","",ROUND(N(P22)+N(AB22),2)) | AF22: =IF($A22="","",ROUND(N(Z22)+N(AC22),2)) | AG22: =IF($A22="","",ROUND(N(AA22)+N(AD22),2)) | AH22: =IF($A22="","",IF(OR($H22="Por confirmar",$H22="Cerrado"),"No","Sí")) | AI22: =IF($A22="","",IF(AH22="No",0,IF(RESUMEN!$B$4="Saldo por pagar al fabricante",AA22,IF(RESUMEN!$B$4="Monto completo del pedido",P22,IF(OR($H22="Embarcando",$H22="Embarcado"),N(AA22),N(P22)))))) | AJ22: =IF($A22="","",IF(COUNTIF($A$4:$A$200,$A22)>1,"ID_Pedido repetido",IF(N($P22)<=0,"Falta el costo del fabricante",IF($F22="","Falta el proyecto",IF($G22="","Falta el cliente",IF(AND($H22<>"Por confirmar",N($R22)>0,$T22=""),"Falta el estado del anticipo",IF(AND($H22<>"Por confirmar",N($V22)>0,$X22=""),"Falta el estado del balance",IF($E22>1,""&$E22&" equipos en una fila: pártela en una por proyecto",IF(AND($X22="Pendiente",N($V22)>0,$W22=""),"Falta la fecha en que vence el balance",IF(AND($H22<>"Por confirmar",$H22<>"Cerrado",$AI22=0),"Consume 0 de cupo pero no está Por confirmar",""))))))))))
A23: 11-4 | B23: 11 | C23: Singsun | D23: Tracker | E23: 1 | F23: Urumita (2) | G23: Solenium | H23: En producción | J23: 46310 | O23: Pending | P23: 60420.49 | Q23: 0.1 | R23: =IF($A23="","",ROUND(P23*Q23,2)) | T23: Pagado | U23: 46268 | V23: =IF($A23="","",ROUND(P23-R23,2)) | X23: Pendiente | Z23: =IF($A23="","",IF(T23="Pagado",N(R23),0)+IF(X23="Pagado",N(V23),0)) | AA23: =IF($A23="","",ROUND(N(P23)-N(Z23),2)) | AB23: =IF($A23="","",SUMIF('OTROS COMPONENTES'!$A$4:$A$200,$A23,'OTROS COMPONENTES'!$D$4:$D$200)) | AC23: =IF($A23="","",SUMIF('OTROS COMPONENTES'!$A$4:$A$200,$A23,'OTROS COMPONENTES'!$E$4:$E$200)) | AD23: =IF($A23="","",ROUND(N(AB23)-N(AC23),2)) | AE23: =IF($A23="","",ROUND(N(P23)+N(AB23),2)) | AF23: =IF($A23="","",ROUND(N(Z23)+N(AC23),2)) | AG23: =IF($A23="","",ROUND(N(AA23)+N(AD23),2)) | AH23: =IF($A23="","",IF(OR($H23="Por confirmar",$H23="Cerrado"),"No","Sí")) | AI23: =IF($A23="","",IF(AH23="No",0,IF(RESUMEN!$B$4="Saldo por pagar al fabricante",AA23,IF(RESUMEN!$B$4="Monto completo del pedido",P23,IF(OR($H23="Embarcando",$H23="Embarcado"),N(AA23),N(P23)))))) | AJ23: =IF($A23="","",IF(COUNTIF($A$4:$A$200,$A23)>1,"ID_Pedido repetido",IF(N($P23)<=0,"Falta el costo del fabricante",IF($F23="","Falta el proyecto",IF($G23="","Falta el cliente",IF(AND($H23<>"Por confirmar",N($R23)>0,$T23=""),"Falta el estado del anticipo",IF(AND($H23<>"Por confirmar",N($V23)>0,$X23=""),"Falta el estado del balance",IF($E23>1,""&$E23&" equipos en una fila: pártela en una por proyecto",IF(AND($X23="Pendiente",N($V23)>0,$W23=""),"Falta la fecha en que vence el balance",IF(AND($H23<>"Por confirmar",$H23<>"Cerrado",$AI23=0),"Consume 0 de cupo pero no está Por confirmar",""))))))))))
A24: CFM2-3 | B24: CFM2 | C24: Eaglerise | D24: Shelter | E24: 4 | G24: Solenium | H24: Embarcado | J24: 46117 | K24: 46150 | M24: 46173 | N24: SHP00992933 | O24: Released | P24: 277400 | Q24: 0.5559 | R24: =IF($A24="","",ROUND(P24*Q24,2)) | T24: Pagado | V24: =IF($A24="","",ROUND(P24-R24,2)) | W24: 46210 | X24: Pendiente | Z24: =IF($A24="","",IF(T24="Pagado",N(R24),0)+IF(X24="Pagado",N(V24),0)) | AA24: =IF($A24="","",ROUND(N(P24)-N(Z24),2)) | AB24: =IF($A24="","",SUMIF('OTROS COMPONENTES'!$A$4:$A$200,$A24,'OTROS COMPONENTES'!$D$4:$D$200)) | AC24: =IF($A24="","",SUMIF('OTROS COMPONENTES'!$A$4:$A$200,$A24,'OTROS COMPONENTES'!$E$4:$E$200)) | AD24: =IF($A24="","",ROUND(N(AB24)-N(AC24),2)) | AE24: =IF($A24="","",ROUND(N(P24)+N(AB24),2)) | AF24: =IF($A24="","",ROUND(N(Z24)+N(AC24),2)) | AG24: =IF($A24="","",ROUND(N(AA24)+N(AD24),2)) | AH24: =IF($A24="","",IF(OR($H24="Por confirmar",$H24="Cerrado"),"No","Sí")) | AI24: =IF($A24="","",IF(AH24="No",0,IF(RESUMEN!$B$4="Saldo por pagar al fabricante",AA24,IF(RESUMEN!$B$4="Monto completo del pedido",P24,IF(OR($H24="Embarcando",$H24="Embarcado"),N(AA24),N(P24)))))) | AJ24: =IF($A24="","",IF(COUNTIF($A$4:$A$200,$A24)>1,"ID_Pedido repetido",IF(N($P24)<=0,"Falta el costo del fabricante",IF($F24="","Falta el proyecto",IF($G24="","Falta el cliente",IF(AND($H24<>"Por confirmar",N($R24)>0,$T24=""),"Falta el estado del anticipo",IF(AND($H24<>"Por confirmar",N($V24)>0,$X24=""),"Falta el estado del balance",IF($E24>1,""&$E24&" equipos en una fila: pártela en una por proyecto",IF(AND($X24="Pendiente",N($V24)>0,$W24=""),"Falta la fecha en que vence el balance",IF(AND($H24<>"Por confirmar",$H24<>"Cerrado",$AI24=0),"Consume 0 de cupo pero no está Por confirmar","")))))))))) | AK24: Estado de pago deducido: venía en blanco en el detailed
A25: CFM3-1 | B25: CFM3 | C25: Eaglerise | D25: Shelter | E25: 4 | F25: Girón Oriente / Curumaní / Galapa | G25: Solenium | H25: Embarcado | J25: 46127 | K25: 46155 | M25: 46180 | N25: SHP0099184 | O25: Released | P25: 257600 | Q25: 0.2 | R25: =IF($A25="","",ROUND(P25*Q25,2)) | T25: Pagado | U25: 46128 | V25: =IF($A25="","",ROUND(P25-R25,2)) | W25: 46215 | X25: Pendiente | Z25: =IF($A25="","",IF(T25="Pagado",N(R25),0)+IF(X25="Pagado",N(V25),0)) | AA25: =IF($A25="","",ROUND(N(P25)-N(Z25),2)) | AB25: =IF($A25="","",SUMIF('OTROS COMPONENTES'!$A$4:$A$200,$A25,'OTROS COMPONENTES'!$D$4:$D$200)) | AC25: =IF($A25="","",SUMIF('OTROS COMPONENTES'!$A$4:$A$200,$A25,'OTROS COMPONENTES'!$E$4:$E$200)) | AD25: =IF($A25="","",ROUND(N(AB25)-N(AC25),2)) | AE25: =IF($A25="","",ROUND(N(P25)+N(AB25),2)) | AF25: =IF($A25="","",ROUND(N(Z25)+N(AC25),2)) | AG25: =IF($A25="","",ROUND(N(AA25)+N(AD25),2)) | AH25: =IF($A25="","",IF(OR($H25="Por confirmar",$H25="Cerrado"),"No","Sí")) | AI25: =IF($A25="","",IF(AH25="No",0,IF(RESUMEN!$B$4="Saldo por pagar al fabricante",AA25,IF(RESUMEN!$B$4="Monto completo del pedido",P25,IF(OR($H25="Embarcando",$H25="Embarcado"),N(AA25),N(P25)))))) | AJ25: =IF($A25="","",IF(COUNTIF($A$4:$A$200,$A25)>1,"ID_Pedido repetido",IF(N($P25)<=0,"Falta el costo del fabricante",IF($F25="","Falta el proyecto",IF($G25="","Falta el cliente",IF(AND($H25<>"Por confirmar",N($R25)>0,$T25=""),"Falta el estado del anticipo",IF(AND($H25<>"Por confirmar",N($V25)>0,$X25=""),"Falta el estado del balance",IF($E25>1,""&$E25&" equipos en una fila: pártela en una por proyecto",IF(AND($X25="Pendiente",N($V25)>0,$W25=""),"Falta la fecha en que vence el balance",IF(AND($H25<>"Por confirmar",$H25<>"Cerrado",$AI25=0),"Consume 0 de cupo pero no está Por confirmar",""))))))))))
A26: CFM3-2 | B26: CFM3 | C26: Eaglerise | D26: Shelter | E26: 2 | G26: Solenium | H26: Embarcado | J26: 46229 | K26: 46239 | M26: 46262 | N26: NSZEC260798655 | O26: Released | P26: 128800 | Q26: 0.2 | R26: =IF($A26="","",ROUND(P26*Q26,2)) | T26: Pagado | U26: 46226 | V26: =IF($A26="","",ROUND(P26-R26,2)) | W26: 46299 | X26: Pendiente | Z26: =IF($A26="","",IF(T26="Pagado",N(R26),0)+IF(X26="Pagado",N(V26),0)) | AA26: =IF($A26="","",ROUND(N(P26)-N(Z26),2)) | AB26: =IF($A26="","",SUMIF('OTROS COMPONENTES'!$A$4:$A$200,$A26,'OTROS COMPONENTES'!$D$4:$D$200)) | AC26: =IF($A26="","",SUMIF('OTROS COMPONENTES'!$A$4:$A$200,$A26,'OTROS COMPONENTES'!$E$4:$E$200)) | AD26: =IF($A26="","",ROUND(N(AB26)-N(AC26),2)) | AE26: =IF($A26="","",ROUND(N(P26)+N(AB26),2)) | AF26: =IF($A26="","",ROUND(N(Z26)+N(AC26),2)) | AG26: =IF($A26="","",ROUND(N(AA26)+N(AD26),2)) | AH26: =IF($A26="","",IF(OR($H26="Por confirmar",$H26="Cerrado"),"No","Sí")) | AI26: =IF($A26="","",IF(AH26="No",0,IF(RESUMEN!$B$4="Saldo por pagar al fabricante",AA26,IF(RESUMEN!$B$4="Monto completo del pedido",P26,IF(OR($H26="Embarcando",$H26="Embarcado"),N(AA26),N(P26)))))) | AJ26: =IF($A26="","",IF(COUNTIF($A$4:$A$200,$A26)>1,"ID_Pedido repetido",IF(N($P26)<=0,"Falta el costo del fabricante",IF($F26="","Falta el proyecto",IF($G26="","Falta el cliente",IF(AND($H26<>"Por confirmar",N($R26)>0,$T26=""),"Falta el estado del anticipo",IF(AND($H26<>"Por confirmar",N($V26)>0,$X26=""),"Falta el estado del balance",IF($E26>1,""&$E26&" equipos en una fila: pártela en una por proyecto",IF(AND($X26="Pendiente",N($V26)>0,$W26=""),"Falta la fecha en que vence el balance",IF(AND($H26<>"Por confirmar",$H26<>"Cerrado",$AI26=0),"Consume 0 de cupo pero no está Por confirmar",""))))))))))
A27: CFM3-3 | B27: CFM3 | C27: Eaglerise | D27: Shelter | E27: 2 | G27: Solenium | H27: Embarcado | J27: 46221 | K27: 46284 | M27: 46326 | O27: Pending | P27: 128800 | Q27: 0.2 | R27: =IF($A27="","",ROUND(P27*Q27,2)) | T27: Pagado | U27: 46266 | V27: =IF($A27="","",ROUND(P27-R27,2)) | W27: 46344 | X27: Pendiente | Z27: =IF($A27="","",IF(T27="Pagado",N(R27),0)+IF(X27="Pagado",N(V27),0)) | AA27: =IF($A27="","",ROUND(N(P27)-N(Z27),2)) | AB27: =IF($A27="","",SUMIF('OTROS COMPONENTES'!$A$4:$A$200,$A27,'OTROS COMPONENTES'!$D$4:$D$200)) | AC27: =IF($A27="","",SUMIF('OTROS COMPONENTES'!$A$4:$A$200,$A27,'OTROS COMPONENTES'!$E$4:$E$200)) | AD27: =IF($A27="","",ROUND(N(AB27)-N(AC27),2)) | AE27: =IF($A27="","",ROUND(N(P27)+N(AB27),2)) | AF27: =IF($A27="","",ROUND(N(Z27)+N(AC27),2)) | AG27: =IF($A27="","",ROUND(N(AA27)+N(AD27),2)) | AH27: =IF($A27="","",IF(OR($H27="Por confirmar",$H27="Cerrado"),"No","Sí")) | AI27: =IF($A27="","",IF(AH27="No",0,IF(RESUMEN!$B$4="Saldo por pagar al fabricante",AA27,IF(RESUMEN!$B$4="Monto completo del pedido",P27,IF(OR($H27="Embarcando",$H27="Embarcado"),N(AA27),N(P27)))))) | AJ27: =IF($A27="","",IF(COUNTIF($A$4:$A$200,$A27)>1,"ID_Pedido repetido",IF(N($P27)<=0,"Falta el costo del fabricante",IF($F27="","Falta el proyecto",IF($G27="","Falta el cliente",IF(AND($H27<>"Por confirmar",N($R27)>0,$T27=""),"Falta el estado del anticipo",IF(AND($H27<>"Por confirmar",N($V27)>0,$X27=""),"Falta el estado del balance",IF($E27>1,""&$E27&" equipos en una fila: pártela en una por proyecto",IF(AND($X27="Pendiente",N($V27)>0,$W27=""),"Falta la fecha en que vence el balance",IF(AND($H27<>"Por confirmar",$H27<>"Cerrado",$AI27=0),"Consume 0 de cupo pero no está Por confirmar",""))))))))))
A28: CFM3-4 | B28: CFM3 | C28: Eaglerise | D28: Shelter | E28: 2 | G28: Solenium | H28: En producción | J28: 46305 | O28: Pending | P28: 128800 | Q28: 0.2 | R28: =IF($A28="","",ROUND(P28*Q28,2)) | T28: Pendiente | V28: =IF($A28="","",ROUND(P28-R28,2)) | W28: 46294 | X28: Pendiente | Z28: =IF($A28="","",IF(T28="Pagado",N(R28),0)+IF(X28="Pagado",N(V28),0)) | AA28: =IF($A28="","",ROUND(N(P28)-N(Z28),2)) | AB28: =IF($A28="","",SUMIF('OTROS COMPONENTES'!$A$4:$A$200,$A28,'OTROS COMPONENTES'!$D$4:$D$200)) | AC28: =IF($A28="","",SUMIF('OTROS COMPONENTES'!$A$4:$A$200,$A28,'OTROS COMPONENTES'!$E$4:$E$200)) | AD28: =IF($A28="","",ROUND(N(AB28)-N(AC28),2)) | AE28: =IF($A28="","",ROUND(N(P28)+N(AB28),2)) | AF28: =IF($A28="","",ROUND(N(Z28)+N(AC28),2)) | AG28: =IF($A28="","",ROUND(N(AA28)+N(AD28),2)) | AH28: =IF($A28="","",IF(OR($H28="Por confirmar",$H28="Cerrado"),"No","Sí")) | AI28: =IF($A28="","",IF(AH28="No",0,IF(RESUMEN!$B$4="Saldo por pagar al fabricante",AA28,IF(RESUMEN!$B$4="Monto completo del pedido",P28,IF(OR($H28="Embarcando",$H28="Embarcado"),N(AA28),N(P28)))))) | AJ28: =IF($A28="","",IF(COUNTIF($A$4:$A$200,$A28)>1,"ID_Pedido repetido",IF(N($P28)<=0,"Falta el costo del fabricante",IF($F28="","Falta el proyecto",IF($G28="","Falta el cliente",IF(AND($H28<>"Por confirmar",N($R28)>0,$T28=""),"Falta el estado del anticipo",IF(AND($H28<>"Por confirmar",N($V28)>0,$X28=""),"Falta el estado del balance",IF($E28>1,""&$E28&" equipos en una fila: pártela en una por proyecto",IF(AND($X28="Pendiente",N($V28)>0,$W28=""),"Falta la fecha en que vence el balance",IF(AND($H28<>"Por confirmar",$H28<>"Cerrado",$AI28=0),"Consume 0 de cupo pero no está Por confirmar",""))))))))))
A29: CFM4 | B29: CFM4 | C29: Eaglerise | D29: Shelter | E29: 4 | G29: Solenium | H29: En producción | J29: 46305 | O29: Pending | P29: 282720 | Q29: 0.2 | R29: =IF($A29="","",ROUND(P29*Q29,2)) | T29: Pendiente | V29: =IF($A29="","",ROUND(P29-R29,2)) | X29: Pendiente | Z29: =IF($A29="","",IF(T29="Pagado",N(R29),0)+IF(X29="Pagado",N(V29),0)) | AA29: =IF($A29="","",ROUND(N(P29)-N(Z29),2)) | AB29: =IF($A29="","",SUMIF('OTROS COMPONENTES'!$A$4:$A$200,$A29,'OTROS COMPONENTES'!$D$4:$D$200)) | AC29: =IF($A29="","",SUMIF('OTROS COMPONENTES'!$A$4:$A$200,$A29,'OTROS COMPONENTES'!$E$4:$E$200)) | AD29: =IF($A29="","",ROUND(N(AB29)-N(AC29),2)) | AE29: =IF($A29="","",ROUND(N(P29)+N(AB29),2)) | AF29: =IF($A29="","",ROUND(N(Z29)+N(AC29),2)) | AG29: =IF($A29="","",ROUND(N(AA29)+N(AD29),2)) | AH29: =IF($A29="","",IF(OR($H29="Por confirmar",$H29="Cerrado"),"No","Sí")) | AI29: =IF($A29="","",IF(AH29="No",0,IF(RESUMEN!$B$4="Saldo por pagar al fabricante",AA29,IF(RESUMEN!$B$4="Monto completo del pedido",P29,IF(OR($H29="Embarcando",$H29="Embarcado"),N(AA29),N(P29)))))) | AJ29: =IF($A29="","",IF(COUNTIF($A$4:$A$200,$A29)>1,"ID_Pedido repetido",IF(N($P29)<=0,"Falta el costo del fabricante",IF($F29="","Falta el proyecto",IF($G29="","Falta el cliente",IF(AND($H29<>"Por confirmar",N($R29)>0,$T29=""),"Falta el estado del anticipo",IF(AND($H29<>"Por confirmar",N($V29)>0,$X29=""),"Falta el estado del balance",IF($E29>1,""&$E29&" equipos en una fila: pártela en una por proyecto",IF(AND($X29="Pendiente",N($V29)>0,$W29=""),"Falta la fecha en que vence el balance",IF(AND($H29<>"Por confirmar",$H29<>"Cerrado",$AI29=0),"Consume 0 de cupo pero no está Por confirmar",""))))))))))
A30: 12 | B30: 12 | C30: Eaglerise | D30: Shelter | E30: 1 | F30: Solaris | G30: Ingenio Verde | H30: Embarcando | J30: 46219 | K30: 46234 | M30: 46268 | N30: SHP0112516 | O30: Released | P30: 72240 | Q30: 0.2 | R30: =IF($A30="","",ROUND(P30*Q30,2)) | T30: Pagado | U30: 46142 | V30: =IF($A30="","",ROUND(P30-R30,2)) | W30: 46294 | X30: Pendiente | Z30: =IF($A30="","",IF(T30="Pagado",N(R30),0)+IF(X30="Pagado",N(V30),0)) | AA30: =IF($A30="","",ROUND(N(P30)-N(Z30),2)) | AB30: =IF($A30="","",SUMIF('OTROS COMPONENTES'!$A$4:$A$200,$A30,'OTROS COMPONENTES'!$D$4:$D$200)) | AC30: =IF($A30="","",SUMIF('OTROS COMPONENTES'!$A$4:$A$200,$A30,'OTROS COMPONENTES'!$E$4:$E$200)) | AD30: =IF($A30="","",ROUND(N(AB30)-N(AC30),2)) | AE30: =IF($A30="","",ROUND(N(P30)+N(AB30),2)) | AF30: =IF($A30="","",ROUND(N(Z30)+N(AC30),2)) | AG30: =IF($A30="","",ROUND(N(AA30)+N(AD30),2)) | AH30: =IF($A30="","",IF(OR($H30="Por confirmar",$H30="Cerrado"),"No","Sí")) | AI30: =IF($A30="","",IF(AH30="No",0,IF(RESUMEN!$B$4="Saldo por pagar al fabricante",AA30,IF(RESUMEN!$B$4="Monto completo del pedido",P30,IF(OR($H30="Embarcando",$H30="Embarcado"),N(AA30),N(P30)))))) | AJ30: =IF($A30="","",IF(COUNTIF($A$4:$A$200,$A30)>1,"ID_Pedido repetido",IF(N($P30)<=0,"Falta el costo del fabricante",IF($F30="","Falta el proyecto",IF($G30="","Falta el cliente",IF(AND($H30<>"Por confirmar",N($R30)>0,$T30=""),"Falta el estado del anticipo",IF(AND($H30<>"Por confirmar",N($V30)>0,$X30=""),"Falta el estado del balance",IF($E30>1,""&$E30&" equipos en una fila: pártela en una por proyecto",IF(AND($X30="Pendiente",N($V30)>0,$W30=""),"Falta la fecha en que vence el balance",IF(AND($H30<>"Por confirmar",$H30<>"Cerrado",$AI30=0),"Consume 0 de cupo pero no está Por confirmar","")))))))))) | AK30: El ORDER REPORT traía 111,701 y el detailed 72,240 — se tomó el del detailed
A31: 13 | B31: 13 | C31: Eaglerise | D31: Shelter | E31: 3 | F31: COX | G31: Solenium | H31: En producción | O31: Pending | P31: 146700 | Q31: 0.2 | R31: =IF($A31="","",ROUND(P31*Q31,2)) | T31: Pendiente | V31: =IF($A31="","",ROUND(P31-R31,2)) | X31: Pendiente | Z31: =IF($A31="","",IF(T31="Pagado",N(R31),0)+IF(X31="Pagado",N(V31),0)) | AA31: =IF($A31="","",ROUND(N(P31)-N(Z31),2)) | AB31: =IF($A31="","",SUMIF('OTROS COMPONENTES'!$A$4:$A$200,$A31,'OTROS COMPONENTES'!$D$4:$D$200)) | AC31: =IF($A31="","",SUMIF('OTROS COMPONENTES'!$A$4:$A$200,$A31,'OTROS COMPONENTES'!$E$4:$E$200)) | AD31: =IF($A31="","",ROUND(N(AB31)-N(AC31),2)) | AE31: =IF($A31="","",ROUND(N(P31)+N(AB31),2)) | AF31: =IF($A31="","",ROUND(N(Z31)+N(AC31),2)) | AG31: =IF($A31="","",ROUND(N(AA31)+N(AD31),2)) | AH31: =IF($A31="","",IF(OR($H31="Por confirmar",$H31="Cerrado"),"No","Sí")) | AI31: =IF($A31="","",IF(AH31="No",0,IF(RESUMEN!$B$4="Saldo por pagar al fabricante",AA31,IF(RESUMEN!$B$4="Monto completo del pedido",P31,IF(OR($H31="Embarcando",$H31="Embarcado"),N(AA31),N(P31)))))) | AJ31: =IF($A31="","",IF(COUNTIF($A$4:$A$200,$A31)>1,"ID_Pedido repetido",IF(N($P31)<=0,"Falta el costo del fabricante",IF($F31="","Falta el proyecto",IF($G31="","Falta el cliente",IF(AND($H31<>"Por confirmar",N($R31)>0,$T31=""),"Falta el estado del anticipo",IF(AND($H31<>"Por confirmar",N($V31)>0,$X31=""),"Falta el estado del balance",IF($E31>1,""&$E31&" equipos en una fila: pártela en una por proyecto",IF(AND($X31="Pendiente",N($V31)>0,$W31=""),"Falta la fecha en que vence el balance",IF(AND($H31<>"Por confirmar",$H31<>"Cerrado",$AI31=0),"Consume 0 de cupo pero no está Por confirmar",""))))))))))
A32: 14 | B32: 14 | C32: Eaglerise | D32: Shelter | E32: 1 | F32: Siliana | G32: Solenium | H32: Embarcando | J32: 46288 | O32: Pending | P32: 72240 | Q32: 0.2 | R32: =IF($A32="","",ROUND(P32*Q32,2)) | T32: Pendiente | V32: =IF($A32="","",ROUND(P32-R32,2)) | W32: 46294 | X32: Pendiente | Z32: =IF($A32="","",IF(T32="Pagado",N(R32),0)+IF(X32="Pagado",N(V32),0)) | AA32: =IF($A32="","",ROUND(N(P32)-N(Z32),2)) | AB32: =IF($A32="","",SUMIF('OTROS COMPONENTES'!$A$4:$A$200,$A32,'OTROS COMPONENTES'!$D$4:$D$200)) | AC32: =IF($A32="","",SUMIF('OTROS COMPONENTES'!$A$4:$A$200,$A32,'OTROS COMPONENTES'!$E$4:$E$200)) | AD32: =IF($A32="","",ROUND(N(AB32)-N(AC32),2)) | AE32: =IF($A32="","",ROUND(N(P32)+N(AB32),2)) | AF32: =IF($A32="","",ROUND(N(Z32)+N(AC32),2)) | AG32: =IF($A32="","",ROUND(N(AA32)+N(AD32),2)) | AH32: =IF($A32="","",IF(OR($H32="Por confirmar",$H32="Cerrado"),"No","Sí")) | AI32: =IF($A32="","",IF(AH32="No",0,IF(RESUMEN!$B$4="Saldo por pagar al fabricante",AA32,IF(RESUMEN!$B$4="Monto completo del pedido",P32,IF(OR($H32="Embarcando",$H32="Embarcado"),N(AA32),N(P32)))))) | AJ32: =IF($A32="","",IF(COUNTIF($A$4:$A$200,$A32)>1,"ID_Pedido repetido",IF(N($P32)<=0,"Falta el costo del fabricante",IF($F32="","Falta el proyecto",IF($G32="","Falta el cliente",IF(AND($H32<>"Por confirmar",N($R32)>0,$T32=""),"Falta el estado del anticipo",IF(AND($H32<>"Por confirmar",N($V32)>0,$X32=""),"Falta el estado del balance",IF($E32>1,""&$E32&" equipos en una fila: pártela en una por proyecto",IF(AND($X32="Pendiente",N($V32)>0,$W32=""),"Falta la fecha en que vence el balance",IF(AND($H32<>"Por confirmar",$H32<>"Cerrado",$AI32=0),"Consume 0 de cupo pero no está Por confirmar",""))))))))))
A33: 15 | B33: 15 | C33: Eaglerise | D33: Shelter | E33: 2 | F33: 3200 msnm | G33: Solenium | H33: En producción | J33: 46326 | O33: Pending | P33: 139000 | Q33: 0.2 | R33: =IF($A33="","",ROUND(P33*Q33,2)) | T33: Pendiente | V33: =IF($A33="","",ROUND(P33-R33,2)) | X33: Pendiente | Z33: =IF($A33="","",IF(T33="Pagado",N(R33),0)+IF(X33="Pagado",N(V33),0)) | AA33: =IF($A33="","",ROUND(N(P33)-N(Z33),2)) | AB33: =IF($A33="","",SUMIF('OTROS COMPONENTES'!$A$4:$A$200,$A33,'OTROS COMPONENTES'!$D$4:$D$200)) | AC33: =IF($A33="","",SUMIF('OTROS COMPONENTES'!$A$4:$A$200,$A33,'OTROS COMPONENTES'!$E$4:$E$200)) | AD33: =IF($A33="","",ROUND(N(AB33)-N(AC33),2)) | AE33: =IF($A33="","",ROUND(N(P33)+N(AB33),2)) | AF33: =IF($A33="","",ROUND(N(Z33)+N(AC33),2)) | AG33: =IF($A33="","",ROUND(N(AA33)+N(AD33),2)) | AH33: =IF($A33="","",IF(OR($H33="Por confirmar",$H33="Cerrado"),"No","Sí")) | AI33: =IF($A33="","",IF(AH33="No",0,IF(RESUMEN!$B$4="Saldo por pagar al fabricante",AA33,IF(RESUMEN!$B$4="Monto completo del pedido",P33,IF(OR($H33="Embarcando",$H33="Embarcado"),N(AA33),N(P33)))))) | AJ33: =IF($A33="","",IF(COUNTIF($A$4:$A$200,$A33)>1,"ID_Pedido repetido",IF(N($P33)<=0,"Falta el costo del fabricante",IF($F33="","Falta el proyecto",IF($G33="","Falta el cliente",IF(AND($H33<>"Por confirmar",N($R33)>0,$T33=""),"Falta el estado del anticipo",IF(AND($H33<>"Por confirmar",N($V33)>0,$X33=""),"Falta el estado del balance",IF($E33>1,""&$E33&" equipos en una fila: pártela en una por proyecto",IF(AND($X33="Pendiente",N($V33)>0,$W33=""),"Falta la fecha en que vence el balance",IF(AND($H33<>"Por confirmar",$H33<>"Cerrado",$AI33=0),"Consume 0 de cupo pero no está Por confirmar",""))))))))))
A34: 16 | B34: 16 | C34: Eaglerise | D34: Shelter | E34: 8 | G34: Solenium | H34: Por confirmar | J34: 46336 | O34: Pending | P34: 515200 | Q34: 0 | R34: =IF($A34="","",ROUND(P34*Q34,2)) | V34: =IF($A34="","",ROUND(P34-R34,2)) | Z34: =IF($A34="","",IF(T34="Pagado",N(R34),0)+IF(X34="Pagado",N(V34),0)) | AA34: =IF($A34="","",ROUND(N(P34)-N(Z34),2)) | AB34: =IF($A34="","",SUMIF('OTROS COMPONENTES'!$A$4:$A$200,$A34,'OTROS COMPONENTES'!$D$4:$D$200)) | AC34: =IF($A34="","",SUMIF('OTROS COMPONENTES'!$A$4:$A$200,$A34,'OTROS COMPONENTES'!$E$4:$E$200)) | AD34: =IF($A34="","",ROUND(N(AB34)-N(AC34),2)) | AE34: =IF($A34="","",ROUND(N(P34)+N(AB34),2)) | AF34: =IF($A34="","",ROUND(N(Z34)+N(AC34),2)) | AG34: =IF($A34="","",ROUND(N(AA34)+N(AD34),2)) | AH34: =IF($A34="","",IF(OR($H34="Por confirmar",$H34="Cerrado"),"No","Sí")) | AI34: =IF($A34="","",IF(AH34="No",0,IF(RESUMEN!$B$4="Saldo por pagar al fabricante",AA34,IF(RESUMEN!$B$4="Monto completo del pedido",P34,IF(OR($H34="Embarcando",$H34="Embarcado"),N(AA34),N(P34)))))) | AJ34: =IF($A34="","",IF(COUNTIF($A$4:$A$200,$A34)>1,"ID_Pedido repetido",IF(N($P34)<=0,"Falta el costo del fabricante",IF($F34="","Falta el proyecto",IF($G34="","Falta el cliente",IF(AND($H34<>"Por confirmar",N($R34)>0,$T34=""),"Falta el estado del anticipo",IF(AND($H34<>"Por confirmar",N($V34)>0,$X34=""),"Falta el estado del balance",IF($E34>1,""&$E34&" equipos en una fila: pártela en una por proyecto",IF(AND($X34="Pendiente",N($V34)>0,$W34=""),"Falta la fecha en que vence el balance",IF(AND($H34<>"Por confirmar",$H34<>"Cerrado",$AI34=0),"Consume 0 de cupo pero no está Por confirmar",""))))))))))
